[2023-03-21T12:53:08.188+0000] {taskinstance.py:1084} INFO - Dependencies all met for dep_context=non-requeueable deps ti=<TaskInstance: batch_pipeline.create_tables scheduled__2023-03-20T00:00:00+00:00 [queued]>
[2023-03-21T12:53:08.219+0000] {taskinstance.py:1084} INFO - Dependencies all met for dep_context=requeueable deps ti=<TaskInstance: batch_pipeline.create_tables scheduled__2023-03-20T00:00:00+00:00 [queued]>
[2023-03-21T12:53:08.220+0000] {taskinstance.py:1282} INFO - 
--------------------------------------------------------------------------------
[2023-03-21T12:53:08.224+0000] {taskinstance.py:1283} INFO - Starting attempt 2 of 2
[2023-03-21T12:53:08.226+0000] {taskinstance.py:1284} INFO - 
--------------------------------------------------------------------------------
[2023-03-21T12:53:08.290+0000] {taskinstance.py:1303} INFO - Executing <Task(PostgresOperator): create_tables> on 2023-03-20 00:00:00+00:00
[2023-03-21T12:53:08.307+0000] {standard_task_runner.py:55} INFO - Started process 570 to run task
[2023-03-21T12:53:08.351+0000] {standard_task_runner.py:82} INFO - Running: ['***', 'tasks', 'run', 'batch_pipeline', 'create_tables', 'scheduled__2023-03-20T00:00:00+00:00', '--job-id', '19', '--raw', '--subdir', 'DAGS_FOLDER/load_csv.py', '--cfg-path', '/tmp/tmpp78p75rc']
[2023-03-21T12:53:08.368+0000] {standard_task_runner.py:83} INFO - Job 19: Subtask create_tables
[2023-03-21T12:53:08.891+0000] {task_command.py:388} INFO - Running <TaskInstance: batch_pipeline.create_tables scheduled__2023-03-20T00:00:00+00:00 [running]> on host 070f7bf9e1a1
[2023-03-21T12:53:09.184+0000] {abstractoperator.py:615} ERROR - Exception rendering Jinja template for task 'create_tables', field 'sql'. Template: 'create_tables.sql'
Traceback (most recent call last):
  File "/home/airflow/.local/lib/python3.7/site-packages/airflow/models/abstractoperator.py", line 607, in _do_render_template_fields
    seen_oids,
  File "/home/airflow/.local/lib/python3.7/site-packages/airflow/models/abstractoperator.py", line 659, in render_template
    template = jinja_env.get_template(value)
  File "/home/airflow/.local/lib/python3.7/site-packages/jinja2/environment.py", line 1010, in get_template
    return self._load_template(name, globals)
  File "/home/airflow/.local/lib/python3.7/site-packages/jinja2/environment.py", line 969, in _load_template
    template = self.loader.load(self, name, self.make_globals(globals))
  File "/home/airflow/.local/lib/python3.7/site-packages/jinja2/loaders.py", line 126, in load
    source, filename, uptodate = self.get_source(environment, name)
  File "/home/airflow/.local/lib/python3.7/site-packages/jinja2/loaders.py", line 218, in get_source
    raise TemplateNotFound(template)
jinja2.exceptions.TemplateNotFound: create_tables.sql
[2023-03-21T12:53:09.206+0000] {taskinstance.py:1775} ERROR - Task failed with exception
Traceback (most recent call last):
  File "/home/airflow/.local/lib/python3.7/site-packages/airflow/models/taskinstance.py", line 1377, in _run_raw_task
    self._execute_task_with_callbacks(context, test_mode)
  File "/home/airflow/.local/lib/python3.7/site-packages/airflow/models/taskinstance.py", line 1495, in _execute_task_with_callbacks
    task_orig = self.render_templates(context=context)
  File "/home/airflow/.local/lib/python3.7/site-packages/airflow/models/taskinstance.py", line 2122, in render_templates
    original_task.render_template_fields(context)
  File "/home/airflow/.local/lib/python3.7/site-packages/airflow/models/baseoperator.py", line 1179, in render_template_fields
    self._do_render_template_fields(self, self.template_fields, context, jinja_env, set())
  File "/home/airflow/.local/lib/python3.7/site-packages/airflow/utils/session.py", line 75, in wrapper
    return func(*args, session=session, **kwargs)
  File "/home/airflow/.local/lib/python3.7/site-packages/airflow/models/abstractoperator.py", line 607, in _do_render_template_fields
    seen_oids,
  File "/home/airflow/.local/lib/python3.7/site-packages/airflow/models/abstractoperator.py", line 659, in render_template
    template = jinja_env.get_template(value)
  File "/home/airflow/.local/lib/python3.7/site-packages/jinja2/environment.py", line 1010, in get_template
    return self._load_template(name, globals)
  File "/home/airflow/.local/lib/python3.7/site-packages/jinja2/environment.py", line 969, in _load_template
    template = self.loader.load(self, name, self.make_globals(globals))
  File "/home/airflow/.local/lib/python3.7/site-packages/jinja2/loaders.py", line 126, in load
    source, filename, uptodate = self.get_source(environment, name)
  File "/home/airflow/.local/lib/python3.7/site-packages/jinja2/loaders.py", line 218, in get_source
    raise TemplateNotFound(template)
jinja2.exceptions.TemplateNotFound: create_tables.sql
[2023-03-21T12:53:09.251+0000] {taskinstance.py:1326} INFO - Marking task as FAILED. dag_id=batch_pipeline, task_id=create_tables, execution_date=20230320T000000, start_date=20230321T125308, end_date=20230321T125309
[2023-03-21T12:53:09.314+0000] {standard_task_runner.py:105} ERROR - Failed to execute job 19 for task create_tables (create_tables.sql; 570)
[2023-03-21T12:53:09.381+0000] {local_task_job.py:212} INFO - Task exited with return code 1
[2023-03-21T12:53:09.493+0000] {taskinstance.py:2585} INFO - 0 downstream tasks scheduled from follow-on schedule check
[2023-03-21T13:42:56.516+0000] {taskinstance.py:1084} INFO - Dependencies all met for dep_context=non-requeueable deps ti=<TaskInstance: batch_pipeline.create_tables scheduled__2023-03-20T00:00:00+00:00 [queued]>
[2023-03-21T13:42:56.539+0000] {taskinstance.py:1084} INFO - Dependencies all met for dep_context=requeueable deps ti=<TaskInstance: batch_pipeline.create_tables scheduled__2023-03-20T00:00:00+00:00 [queued]>
[2023-03-21T13:42:56.541+0000] {taskinstance.py:1282} INFO - 
--------------------------------------------------------------------------------
[2023-03-21T13:42:56.543+0000] {taskinstance.py:1283} INFO - Starting attempt 2 of 2
[2023-03-21T13:42:56.545+0000] {taskinstance.py:1284} INFO - 
--------------------------------------------------------------------------------
[2023-03-21T13:42:56.582+0000] {taskinstance.py:1303} INFO - Executing <Task(PostgresOperator): create_tables> on 2023-03-20 00:00:00+00:00
[2023-03-21T13:42:56.594+0000] {standard_task_runner.py:55} INFO - Started process 1564 to run task
[2023-03-21T13:42:56.610+0000] {standard_task_runner.py:82} INFO - Running: ['***', 'tasks', 'run', 'batch_pipeline', 'create_tables', 'scheduled__2023-03-20T00:00:00+00:00', '--job-id', '88', '--raw', '--subdir', 'DAGS_FOLDER/batch_pipeline.py', '--cfg-path', '/tmp/tmpwxugv51g']
[2023-03-21T13:42:56.612+0000] {standard_task_runner.py:83} INFO - Job 88: Subtask create_tables
[2023-03-21T13:42:56.755+0000] {task_command.py:388} INFO - Running <TaskInstance: batch_pipeline.create_tables scheduled__2023-03-20T00:00:00+00:00 [running]> on host 070f7bf9e1a1
[2023-03-21T13:42:56.829+0000] {abstractoperator.py:615} ERROR - Exception rendering Jinja template for task 'create_tables', field 'sql'. Template: 'create_tables.sql'
Traceback (most recent call last):
  File "/home/airflow/.local/lib/python3.7/site-packages/airflow/models/abstractoperator.py", line 607, in _do_render_template_fields
    seen_oids,
  File "/home/airflow/.local/lib/python3.7/site-packages/airflow/models/abstractoperator.py", line 659, in render_template
    template = jinja_env.get_template(value)
  File "/home/airflow/.local/lib/python3.7/site-packages/jinja2/environment.py", line 1010, in get_template
    return self._load_template(name, globals)
  File "/home/airflow/.local/lib/python3.7/site-packages/jinja2/environment.py", line 969, in _load_template
    template = self.loader.load(self, name, self.make_globals(globals))
  File "/home/airflow/.local/lib/python3.7/site-packages/jinja2/loaders.py", line 126, in load
    source, filename, uptodate = self.get_source(environment, name)
  File "/home/airflow/.local/lib/python3.7/site-packages/jinja2/loaders.py", line 218, in get_source
    raise TemplateNotFound(template)
jinja2.exceptions.TemplateNotFound: create_tables.sql
[2023-03-21T13:42:56.835+0000] {taskinstance.py:1775} ERROR - Task failed with exception
Traceback (most recent call last):
  File "/home/airflow/.local/lib/python3.7/site-packages/airflow/models/taskinstance.py", line 1377, in _run_raw_task
    self._execute_task_with_callbacks(context, test_mode)
  File "/home/airflow/.local/lib/python3.7/site-packages/airflow/models/taskinstance.py", line 1495, in _execute_task_with_callbacks
    task_orig = self.render_templates(context=context)
  File "/home/airflow/.local/lib/python3.7/site-packages/airflow/models/taskinstance.py", line 2122, in render_templates
    original_task.render_template_fields(context)
  File "/home/airflow/.local/lib/python3.7/site-packages/airflow/models/baseoperator.py", line 1179, in render_template_fields
    self._do_render_template_fields(self, self.template_fields, context, jinja_env, set())
  File "/home/airflow/.local/lib/python3.7/site-packages/airflow/utils/session.py", line 75, in wrapper
    return func(*args, session=session, **kwargs)
  File "/home/airflow/.local/lib/python3.7/site-packages/airflow/models/abstractoperator.py", line 607, in _do_render_template_fields
    seen_oids,
  File "/home/airflow/.local/lib/python3.7/site-packages/airflow/models/abstractoperator.py", line 659, in render_template
    template = jinja_env.get_template(value)
  File "/home/airflow/.local/lib/python3.7/site-packages/jinja2/environment.py", line 1010, in get_template
    return self._load_template(name, globals)
  File "/home/airflow/.local/lib/python3.7/site-packages/jinja2/environment.py", line 969, in _load_template
    template = self.loader.load(self, name, self.make_globals(globals))
  File "/home/airflow/.local/lib/python3.7/site-packages/jinja2/loaders.py", line 126, in load
    source, filename, uptodate = self.get_source(environment, name)
  File "/home/airflow/.local/lib/python3.7/site-packages/jinja2/loaders.py", line 218, in get_source
    raise TemplateNotFound(template)
jinja2.exceptions.TemplateNotFound: create_tables.sql
[2023-03-21T13:42:56.853+0000] {taskinstance.py:1326} INFO - Marking task as FAILED. dag_id=batch_pipeline, task_id=create_tables, execution_date=20230320T000000, start_date=20230321T134256, end_date=20230321T134256
[2023-03-21T13:42:56.883+0000] {standard_task_runner.py:105} ERROR - Failed to execute job 88 for task create_tables (create_tables.sql; 1564)
[2023-03-21T13:42:56.941+0000] {local_task_job.py:212} INFO - Task exited with return code 1
[2023-03-21T13:42:56.993+0000] {taskinstance.py:2585} INFO - 0 downstream tasks scheduled from follow-on schedule check
[2023-03-21T13:59:42.487+0000] {taskinstance.py:1084} INFO - Dependencies all met for dep_context=non-requeueable deps ti=<TaskInstance: batch_pipeline.create_tables scheduled__2023-03-20T00:00:00+00:00 [queued]>
[2023-03-21T13:59:42.507+0000] {taskinstance.py:1084} INFO - Dependencies all met for dep_context=requeueable deps ti=<TaskInstance: batch_pipeline.create_tables scheduled__2023-03-20T00:00:00+00:00 [queued]>
[2023-03-21T13:59:42.509+0000] {taskinstance.py:1282} INFO - 
--------------------------------------------------------------------------------
[2023-03-21T13:59:42.511+0000] {taskinstance.py:1283} INFO - Starting attempt 2 of 2
[2023-03-21T13:59:42.513+0000] {taskinstance.py:1284} INFO - 
--------------------------------------------------------------------------------
[2023-03-21T13:59:42.553+0000] {taskinstance.py:1303} INFO - Executing <Task(PostgresOperator): create_tables> on 2023-03-20 00:00:00+00:00
[2023-03-21T13:59:42.567+0000] {standard_task_runner.py:55} INFO - Started process 1881 to run task
[2023-03-21T13:59:42.593+0000] {standard_task_runner.py:82} INFO - Running: ['***', 'tasks', 'run', 'batch_pipeline', 'create_tables', 'scheduled__2023-03-20T00:00:00+00:00', '--job-id', '100', '--raw', '--subdir', 'DAGS_FOLDER/load_csv.py', '--cfg-path', '/tmp/tmphxped95i']
[2023-03-21T13:59:42.597+0000] {standard_task_runner.py:83} INFO - Job 100: Subtask create_tables
[2023-03-21T13:59:42.873+0000] {task_command.py:388} INFO - Running <TaskInstance: batch_pipeline.create_tables scheduled__2023-03-20T00:00:00+00:00 [running]> on host 070f7bf9e1a1
[2023-03-21T13:59:42.966+0000] {abstractoperator.py:615} ERROR - Exception rendering Jinja template for task 'create_tables', field 'sql'. Template: 'create_tables.sql'
Traceback (most recent call last):
  File "/home/airflow/.local/lib/python3.7/site-packages/airflow/models/abstractoperator.py", line 607, in _do_render_template_fields
    seen_oids,
  File "/home/airflow/.local/lib/python3.7/site-packages/airflow/models/abstractoperator.py", line 659, in render_template
    template = jinja_env.get_template(value)
  File "/home/airflow/.local/lib/python3.7/site-packages/jinja2/environment.py", line 1010, in get_template
    return self._load_template(name, globals)
  File "/home/airflow/.local/lib/python3.7/site-packages/jinja2/environment.py", line 969, in _load_template
    template = self.loader.load(self, name, self.make_globals(globals))
  File "/home/airflow/.local/lib/python3.7/site-packages/jinja2/loaders.py", line 126, in load
    source, filename, uptodate = self.get_source(environment, name)
  File "/home/airflow/.local/lib/python3.7/site-packages/jinja2/loaders.py", line 218, in get_source
    raise TemplateNotFound(template)
jinja2.exceptions.TemplateNotFound: create_tables.sql
[2023-03-21T13:59:42.972+0000] {taskinstance.py:1775} ERROR - Task failed with exception
Traceback (most recent call last):
  File "/home/airflow/.local/lib/python3.7/site-packages/airflow/models/taskinstance.py", line 1377, in _run_raw_task
    self._execute_task_with_callbacks(context, test_mode)
  File "/home/airflow/.local/lib/python3.7/site-packages/airflow/models/taskinstance.py", line 1495, in _execute_task_with_callbacks
    task_orig = self.render_templates(context=context)
  File "/home/airflow/.local/lib/python3.7/site-packages/airflow/models/taskinstance.py", line 2122, in render_templates
    original_task.render_template_fields(context)
  File "/home/airflow/.local/lib/python3.7/site-packages/airflow/models/baseoperator.py", line 1179, in render_template_fields
    self._do_render_template_fields(self, self.template_fields, context, jinja_env, set())
  File "/home/airflow/.local/lib/python3.7/site-packages/airflow/utils/session.py", line 75, in wrapper
    return func(*args, session=session, **kwargs)
  File "/home/airflow/.local/lib/python3.7/site-packages/airflow/models/abstractoperator.py", line 607, in _do_render_template_fields
    seen_oids,
  File "/home/airflow/.local/lib/python3.7/site-packages/airflow/models/abstractoperator.py", line 659, in render_template
    template = jinja_env.get_template(value)
  File "/home/airflow/.local/lib/python3.7/site-packages/jinja2/environment.py", line 1010, in get_template
    return self._load_template(name, globals)
  File "/home/airflow/.local/lib/python3.7/site-packages/jinja2/environment.py", line 969, in _load_template
    template = self.loader.load(self, name, self.make_globals(globals))
  File "/home/airflow/.local/lib/python3.7/site-packages/jinja2/loaders.py", line 126, in load
    source, filename, uptodate = self.get_source(environment, name)
  File "/home/airflow/.local/lib/python3.7/site-packages/jinja2/loaders.py", line 218, in get_source
    raise TemplateNotFound(template)
jinja2.exceptions.TemplateNotFound: create_tables.sql
[2023-03-21T13:59:43.000+0000] {taskinstance.py:1326} INFO - Marking task as FAILED. dag_id=batch_pipeline, task_id=create_tables, execution_date=20230320T000000, start_date=20230321T135942, end_date=20230321T135942
[2023-03-21T13:59:43.033+0000] {standard_task_runner.py:105} ERROR - Failed to execute job 100 for task create_tables (create_tables.sql; 1881)
[2023-03-21T13:59:43.100+0000] {local_task_job.py:212} INFO - Task exited with return code 1
[2023-03-21T13:59:43.173+0000] {taskinstance.py:2585} INFO - 0 downstream tasks scheduled from follow-on schedule check
[2023-03-21T15:16:16.973+0000] {taskinstance.py:1084} INFO - Dependencies all met for dep_context=non-requeueable deps ti=<TaskInstance: batch_pipeline.create_tables scheduled__2023-03-20T00:00:00+00:00 [queued]>
[2023-03-21T15:16:16.999+0000] {taskinstance.py:1084} INFO - Dependencies all met for dep_context=requeueable deps ti=<TaskInstance: batch_pipeline.create_tables scheduled__2023-03-20T00:00:00+00:00 [queued]>
[2023-03-21T15:16:17.001+0000] {taskinstance.py:1282} INFO - 
--------------------------------------------------------------------------------
[2023-03-21T15:16:17.004+0000] {taskinstance.py:1283} INFO - Starting attempt 2 of 2
[2023-03-21T15:16:17.011+0000] {taskinstance.py:1284} INFO - 
--------------------------------------------------------------------------------
[2023-03-21T15:16:17.055+0000] {taskinstance.py:1303} INFO - Executing <Task(PostgresOperator): create_tables> on 2023-03-20 00:00:00+00:00
[2023-03-21T15:16:17.071+0000] {standard_task_runner.py:55} INFO - Started process 3148 to run task
[2023-03-21T15:16:17.084+0000] {standard_task_runner.py:82} INFO - Running: ['***', 'tasks', 'run', 'batch_pipeline', 'create_tables', 'scheduled__2023-03-20T00:00:00+00:00', '--job-id', '115', '--raw', '--subdir', 'DAGS_FOLDER/load_csv.py', '--cfg-path', '/tmp/tmpx8j2jl6p']
[2023-03-21T15:16:17.088+0000] {standard_task_runner.py:83} INFO - Job 115: Subtask create_tables
[2023-03-21T15:16:17.333+0000] {task_command.py:388} INFO - Running <TaskInstance: batch_pipeline.create_tables scheduled__2023-03-20T00:00:00+00:00 [running]> on host 070f7bf9e1a1
[2023-03-21T15:16:17.422+0000] {abstractoperator.py:615} ERROR - Exception rendering Jinja template for task 'create_tables', field 'sql'. Template: 'create_tables.sql'
Traceback (most recent call last):
  File "/home/airflow/.local/lib/python3.7/site-packages/airflow/models/abstractoperator.py", line 607, in _do_render_template_fields
    seen_oids,
  File "/home/airflow/.local/lib/python3.7/site-packages/airflow/models/abstractoperator.py", line 659, in render_template
    template = jinja_env.get_template(value)
  File "/home/airflow/.local/lib/python3.7/site-packages/jinja2/environment.py", line 1010, in get_template
    return self._load_template(name, globals)
  File "/home/airflow/.local/lib/python3.7/site-packages/jinja2/environment.py", line 969, in _load_template
    template = self.loader.load(self, name, self.make_globals(globals))
  File "/home/airflow/.local/lib/python3.7/site-packages/jinja2/loaders.py", line 126, in load
    source, filename, uptodate = self.get_source(environment, name)
  File "/home/airflow/.local/lib/python3.7/site-packages/jinja2/loaders.py", line 218, in get_source
    raise TemplateNotFound(template)
jinja2.exceptions.TemplateNotFound: create_tables.sql
[2023-03-21T15:16:17.430+0000] {taskinstance.py:1775} ERROR - Task failed with exception
Traceback (most recent call last):
  File "/home/airflow/.local/lib/python3.7/site-packages/airflow/models/taskinstance.py", line 1377, in _run_raw_task
    self._execute_task_with_callbacks(context, test_mode)
  File "/home/airflow/.local/lib/python3.7/site-packages/airflow/models/taskinstance.py", line 1495, in _execute_task_with_callbacks
    task_orig = self.render_templates(context=context)
  File "/home/airflow/.local/lib/python3.7/site-packages/airflow/models/taskinstance.py", line 2122, in render_templates
    original_task.render_template_fields(context)
  File "/home/airflow/.local/lib/python3.7/site-packages/airflow/models/baseoperator.py", line 1179, in render_template_fields
    self._do_render_template_fields(self, self.template_fields, context, jinja_env, set())
  File "/home/airflow/.local/lib/python3.7/site-packages/airflow/utils/session.py", line 75, in wrapper
    return func(*args, session=session, **kwargs)
  File "/home/airflow/.local/lib/python3.7/site-packages/airflow/models/abstractoperator.py", line 607, in _do_render_template_fields
    seen_oids,
  File "/home/airflow/.local/lib/python3.7/site-packages/airflow/models/abstractoperator.py", line 659, in render_template
    template = jinja_env.get_template(value)
  File "/home/airflow/.local/lib/python3.7/site-packages/jinja2/environment.py", line 1010, in get_template
    return self._load_template(name, globals)
  File "/home/airflow/.local/lib/python3.7/site-packages/jinja2/environment.py", line 969, in _load_template
    template = self.loader.load(self, name, self.make_globals(globals))
  File "/home/airflow/.local/lib/python3.7/site-packages/jinja2/loaders.py", line 126, in load
    source, filename, uptodate = self.get_source(environment, name)
  File "/home/airflow/.local/lib/python3.7/site-packages/jinja2/loaders.py", line 218, in get_source
    raise TemplateNotFound(template)
jinja2.exceptions.TemplateNotFound: create_tables.sql
[2023-03-21T15:16:17.458+0000] {taskinstance.py:1326} INFO - Marking task as FAILED. dag_id=batch_pipeline, task_id=create_tables, execution_date=20230320T000000, start_date=20230321T151616, end_date=20230321T151617
[2023-03-21T15:16:17.491+0000] {standard_task_runner.py:105} ERROR - Failed to execute job 115 for task create_tables (create_tables.sql; 3148)
[2023-03-21T15:16:17.549+0000] {local_task_job.py:212} INFO - Task exited with return code 1
[2023-03-21T15:16:17.641+0000] {taskinstance.py:2585} INFO - 0 downstream tasks scheduled from follow-on schedule check
[2023-03-21T15:25:28.800+0000] {taskinstance.py:1084} INFO - Dependencies all met for dep_context=non-requeueable deps ti=<TaskInstance: batch_pipeline.create_tables scheduled__2023-03-20T00:00:00+00:00 [queued]>
[2023-03-21T15:25:28.828+0000] {taskinstance.py:1084} INFO - Dependencies all met for dep_context=requeueable deps ti=<TaskInstance: batch_pipeline.create_tables scheduled__2023-03-20T00:00:00+00:00 [queued]>
[2023-03-21T15:25:28.830+0000] {taskinstance.py:1282} INFO - 
--------------------------------------------------------------------------------
[2023-03-21T15:25:28.832+0000] {taskinstance.py:1283} INFO - Starting attempt 2 of 2
[2023-03-21T15:25:28.833+0000] {taskinstance.py:1284} INFO - 
--------------------------------------------------------------------------------
[2023-03-21T15:25:28.880+0000] {taskinstance.py:1303} INFO - Executing <Task(PostgresOperator): create_tables> on 2023-03-20 00:00:00+00:00
[2023-03-21T15:25:28.902+0000] {standard_task_runner.py:55} INFO - Started process 3323 to run task
[2023-03-21T15:25:28.916+0000] {standard_task_runner.py:82} INFO - Running: ['***', 'tasks', 'run', 'batch_pipeline', 'create_tables', 'scheduled__2023-03-20T00:00:00+00:00', '--job-id', '127', '--raw', '--subdir', 'DAGS_FOLDER/batch_pipeline.py', '--cfg-path', '/tmp/tmp9c6f5v07']
[2023-03-21T15:25:28.927+0000] {standard_task_runner.py:83} INFO - Job 127: Subtask create_tables
[2023-03-21T15:25:29.129+0000] {task_command.py:388} INFO - Running <TaskInstance: batch_pipeline.create_tables scheduled__2023-03-20T00:00:00+00:00 [running]> on host 070f7bf9e1a1
[2023-03-21T15:25:29.235+0000] {abstractoperator.py:615} ERROR - Exception rendering Jinja template for task 'create_tables', field 'sql'. Template: 'create_tables.sql'
Traceback (most recent call last):
  File "/home/airflow/.local/lib/python3.7/site-packages/airflow/models/abstractoperator.py", line 607, in _do_render_template_fields
    seen_oids,
  File "/home/airflow/.local/lib/python3.7/site-packages/airflow/models/abstractoperator.py", line 659, in render_template
    template = jinja_env.get_template(value)
  File "/home/airflow/.local/lib/python3.7/site-packages/jinja2/environment.py", line 1010, in get_template
    return self._load_template(name, globals)
  File "/home/airflow/.local/lib/python3.7/site-packages/jinja2/environment.py", line 969, in _load_template
    template = self.loader.load(self, name, self.make_globals(globals))
  File "/home/airflow/.local/lib/python3.7/site-packages/jinja2/loaders.py", line 126, in load
    source, filename, uptodate = self.get_source(environment, name)
  File "/home/airflow/.local/lib/python3.7/site-packages/jinja2/loaders.py", line 218, in get_source
    raise TemplateNotFound(template)
jinja2.exceptions.TemplateNotFound: create_tables.sql
[2023-03-21T15:25:29.242+0000] {taskinstance.py:1775} ERROR - Task failed with exception
Traceback (most recent call last):
  File "/home/airflow/.local/lib/python3.7/site-packages/airflow/models/taskinstance.py", line 1377, in _run_raw_task
    self._execute_task_with_callbacks(context, test_mode)
  File "/home/airflow/.local/lib/python3.7/site-packages/airflow/models/taskinstance.py", line 1495, in _execute_task_with_callbacks
    task_orig = self.render_templates(context=context)
  File "/home/airflow/.local/lib/python3.7/site-packages/airflow/models/taskinstance.py", line 2122, in render_templates
    original_task.render_template_fields(context)
  File "/home/airflow/.local/lib/python3.7/site-packages/airflow/models/baseoperator.py", line 1179, in render_template_fields
    self._do_render_template_fields(self, self.template_fields, context, jinja_env, set())
  File "/home/airflow/.local/lib/python3.7/site-packages/airflow/utils/session.py", line 75, in wrapper
    return func(*args, session=session, **kwargs)
  File "/home/airflow/.local/lib/python3.7/site-packages/airflow/models/abstractoperator.py", line 607, in _do_render_template_fields
    seen_oids,
  File "/home/airflow/.local/lib/python3.7/site-packages/airflow/models/abstractoperator.py", line 659, in render_template
    template = jinja_env.get_template(value)
  File "/home/airflow/.local/lib/python3.7/site-packages/jinja2/environment.py", line 1010, in get_template
    return self._load_template(name, globals)
  File "/home/airflow/.local/lib/python3.7/site-packages/jinja2/environment.py", line 969, in _load_template
    template = self.loader.load(self, name, self.make_globals(globals))
  File "/home/airflow/.local/lib/python3.7/site-packages/jinja2/loaders.py", line 126, in load
    source, filename, uptodate = self.get_source(environment, name)
  File "/home/airflow/.local/lib/python3.7/site-packages/jinja2/loaders.py", line 218, in get_source
    raise TemplateNotFound(template)
jinja2.exceptions.TemplateNotFound: create_tables.sql
[2023-03-21T15:25:29.272+0000] {taskinstance.py:1326} INFO - Marking task as FAILED. dag_id=batch_pipeline, task_id=create_tables, execution_date=20230320T000000, start_date=20230321T152528, end_date=20230321T152529
[2023-03-21T15:25:29.304+0000] {standard_task_runner.py:105} ERROR - Failed to execute job 127 for task create_tables (create_tables.sql; 3323)
[2023-03-21T15:25:29.342+0000] {local_task_job.py:212} INFO - Task exited with return code 1
[2023-03-21T15:25:29.441+0000] {taskinstance.py:2585} INFO - 0 downstream tasks scheduled from follow-on schedule check
[2023-03-21T15:49:27.132+0000] {taskinstance.py:1084} INFO - Dependencies all met for dep_context=non-requeueable deps ti=<TaskInstance: batch_pipeline.create_tables scheduled__2023-03-20T00:00:00+00:00 [queued]>
[2023-03-21T15:49:27.172+0000] {taskinstance.py:1084} INFO - Dependencies all met for dep_context=requeueable deps ti=<TaskInstance: batch_pipeline.create_tables scheduled__2023-03-20T00:00:00+00:00 [queued]>
[2023-03-21T15:49:27.174+0000] {taskinstance.py:1282} INFO - 
--------------------------------------------------------------------------------
[2023-03-21T15:49:27.176+0000] {taskinstance.py:1283} INFO - Starting attempt 2 of 2
[2023-03-21T15:49:27.178+0000] {taskinstance.py:1284} INFO - 
--------------------------------------------------------------------------------
[2023-03-21T15:49:27.228+0000] {taskinstance.py:1303} INFO - Executing <Task(PostgresOperator): create_tables> on 2023-03-20 00:00:00+00:00
[2023-03-21T15:49:27.248+0000] {standard_task_runner.py:55} INFO - Started process 3766 to run task
[2023-03-21T15:49:27.268+0000] {standard_task_runner.py:82} INFO - Running: ['***', 'tasks', 'run', 'batch_pipeline', 'create_tables', 'scheduled__2023-03-20T00:00:00+00:00', '--job-id', '151', '--raw', '--subdir', 'DAGS_FOLDER/batch_pipeline.py', '--cfg-path', '/tmp/tmpapnbfvg0']
[2023-03-21T15:49:27.279+0000] {standard_task_runner.py:83} INFO - Job 151: Subtask create_tables
[2023-03-21T15:49:27.528+0000] {task_command.py:388} INFO - Running <TaskInstance: batch_pipeline.create_tables scheduled__2023-03-20T00:00:00+00:00 [running]> on host 070f7bf9e1a1
[2023-03-21T15:49:27.629+0000] {abstractoperator.py:615} ERROR - Exception rendering Jinja template for task 'create_tables', field 'sql'. Template: 'create_tables.sql'
Traceback (most recent call last):
  File "/home/airflow/.local/lib/python3.7/site-packages/airflow/models/abstractoperator.py", line 607, in _do_render_template_fields
    seen_oids,
  File "/home/airflow/.local/lib/python3.7/site-packages/airflow/models/abstractoperator.py", line 659, in render_template
    template = jinja_env.get_template(value)
  File "/home/airflow/.local/lib/python3.7/site-packages/jinja2/environment.py", line 1010, in get_template
    return self._load_template(name, globals)
  File "/home/airflow/.local/lib/python3.7/site-packages/jinja2/environment.py", line 969, in _load_template
    template = self.loader.load(self, name, self.make_globals(globals))
  File "/home/airflow/.local/lib/python3.7/site-packages/jinja2/loaders.py", line 126, in load
    source, filename, uptodate = self.get_source(environment, name)
  File "/home/airflow/.local/lib/python3.7/site-packages/jinja2/loaders.py", line 218, in get_source
    raise TemplateNotFound(template)
jinja2.exceptions.TemplateNotFound: create_tables.sql
[2023-03-21T15:49:27.634+0000] {taskinstance.py:1775} ERROR - Task failed with exception
Traceback (most recent call last):
  File "/home/airflow/.local/lib/python3.7/site-packages/airflow/models/taskinstance.py", line 1377, in _run_raw_task
    self._execute_task_with_callbacks(context, test_mode)
  File "/home/airflow/.local/lib/python3.7/site-packages/airflow/models/taskinstance.py", line 1495, in _execute_task_with_callbacks
    task_orig = self.render_templates(context=context)
  File "/home/airflow/.local/lib/python3.7/site-packages/airflow/models/taskinstance.py", line 2122, in render_templates
    original_task.render_template_fields(context)
  File "/home/airflow/.local/lib/python3.7/site-packages/airflow/models/baseoperator.py", line 1179, in render_template_fields
    self._do_render_template_fields(self, self.template_fields, context, jinja_env, set())
  File "/home/airflow/.local/lib/python3.7/site-packages/airflow/utils/session.py", line 75, in wrapper
    return func(*args, session=session, **kwargs)
  File "/home/airflow/.local/lib/python3.7/site-packages/airflow/models/abstractoperator.py", line 607, in _do_render_template_fields
    seen_oids,
  File "/home/airflow/.local/lib/python3.7/site-packages/airflow/models/abstractoperator.py", line 659, in render_template
    template = jinja_env.get_template(value)
  File "/home/airflow/.local/lib/python3.7/site-packages/jinja2/environment.py", line 1010, in get_template
    return self._load_template(name, globals)
  File "/home/airflow/.local/lib/python3.7/site-packages/jinja2/environment.py", line 969, in _load_template
    template = self.loader.load(self, name, self.make_globals(globals))
  File "/home/airflow/.local/lib/python3.7/site-packages/jinja2/loaders.py", line 126, in load
    source, filename, uptodate = self.get_source(environment, name)
  File "/home/airflow/.local/lib/python3.7/site-packages/jinja2/loaders.py", line 218, in get_source
    raise TemplateNotFound(template)
jinja2.exceptions.TemplateNotFound: create_tables.sql
[2023-03-21T15:49:27.660+0000] {taskinstance.py:1326} INFO - Marking task as FAILED. dag_id=batch_pipeline, task_id=create_tables, execution_date=20230320T000000, start_date=20230321T154927, end_date=20230321T154927
[2023-03-21T15:49:27.695+0000] {standard_task_runner.py:105} ERROR - Failed to execute job 151 for task create_tables (create_tables.sql; 3766)
[2023-03-21T15:49:27.770+0000] {local_task_job.py:212} INFO - Task exited with return code 1
[2023-03-21T15:49:27.884+0000] {taskinstance.py:2585} INFO - 0 downstream tasks scheduled from follow-on schedule check
[2023-03-21T16:00:50.784+0000] {taskinstance.py:1084} INFO - Dependencies all met for dep_context=non-requeueable deps ti=<TaskInstance: batch_pipeline.create_tables scheduled__2023-03-20T00:00:00+00:00 [queued]>
[2023-03-21T16:00:50.805+0000] {taskinstance.py:1084} INFO - Dependencies all met for dep_context=requeueable deps ti=<TaskInstance: batch_pipeline.create_tables scheduled__2023-03-20T00:00:00+00:00 [queued]>
[2023-03-21T16:00:50.811+0000] {taskinstance.py:1282} INFO - 
--------------------------------------------------------------------------------
[2023-03-21T16:00:50.813+0000] {taskinstance.py:1283} INFO - Starting attempt 2 of 2
[2023-03-21T16:00:50.816+0000] {taskinstance.py:1284} INFO - 
--------------------------------------------------------------------------------
[2023-03-21T16:00:50.856+0000] {taskinstance.py:1303} INFO - Executing <Task(PostgresOperator): create_tables> on 2023-03-20 00:00:00+00:00
[2023-03-21T16:00:50.876+0000] {standard_task_runner.py:55} INFO - Started process 3978 to run task
[2023-03-21T16:00:50.895+0000] {standard_task_runner.py:82} INFO - Running: ['***', 'tasks', 'run', 'batch_pipeline', 'create_tables', 'scheduled__2023-03-20T00:00:00+00:00', '--job-id', '166', '--raw', '--subdir', 'DAGS_FOLDER/load_csv.py', '--cfg-path', '/tmp/tmp3j5v52ru']
[2023-03-21T16:00:50.898+0000] {standard_task_runner.py:83} INFO - Job 166: Subtask create_tables
[2023-03-21T16:00:51.093+0000] {task_command.py:388} INFO - Running <TaskInstance: batch_pipeline.create_tables scheduled__2023-03-20T00:00:00+00:00 [running]> on host 070f7bf9e1a1
[2023-03-21T16:00:51.183+0000] {abstractoperator.py:615} ERROR - Exception rendering Jinja template for task 'create_tables', field 'sql'. Template: 'create_tables.sql'
Traceback (most recent call last):
  File "/home/airflow/.local/lib/python3.7/site-packages/airflow/models/abstractoperator.py", line 607, in _do_render_template_fields
    seen_oids,
  File "/home/airflow/.local/lib/python3.7/site-packages/airflow/models/abstractoperator.py", line 659, in render_template
    template = jinja_env.get_template(value)
  File "/home/airflow/.local/lib/python3.7/site-packages/jinja2/environment.py", line 1010, in get_template
    return self._load_template(name, globals)
  File "/home/airflow/.local/lib/python3.7/site-packages/jinja2/environment.py", line 969, in _load_template
    template = self.loader.load(self, name, self.make_globals(globals))
  File "/home/airflow/.local/lib/python3.7/site-packages/jinja2/loaders.py", line 126, in load
    source, filename, uptodate = self.get_source(environment, name)
  File "/home/airflow/.local/lib/python3.7/site-packages/jinja2/loaders.py", line 218, in get_source
    raise TemplateNotFound(template)
jinja2.exceptions.TemplateNotFound: create_tables.sql
[2023-03-21T16:00:51.191+0000] {taskinstance.py:1775} ERROR - Task failed with exception
Traceback (most recent call last):
  File "/home/airflow/.local/lib/python3.7/site-packages/airflow/models/taskinstance.py", line 1377, in _run_raw_task
    self._execute_task_with_callbacks(context, test_mode)
  File "/home/airflow/.local/lib/python3.7/site-packages/airflow/models/taskinstance.py", line 1495, in _execute_task_with_callbacks
    task_orig = self.render_templates(context=context)
  File "/home/airflow/.local/lib/python3.7/site-packages/airflow/models/taskinstance.py", line 2122, in render_templates
    original_task.render_template_fields(context)
  File "/home/airflow/.local/lib/python3.7/site-packages/airflow/models/baseoperator.py", line 1179, in render_template_fields
    self._do_render_template_fields(self, self.template_fields, context, jinja_env, set())
  File "/home/airflow/.local/lib/python3.7/site-packages/airflow/utils/session.py", line 75, in wrapper
    return func(*args, session=session, **kwargs)
  File "/home/airflow/.local/lib/python3.7/site-packages/airflow/models/abstractoperator.py", line 607, in _do_render_template_fields
    seen_oids,
  File "/home/airflow/.local/lib/python3.7/site-packages/airflow/models/abstractoperator.py", line 659, in render_template
    template = jinja_env.get_template(value)
  File "/home/airflow/.local/lib/python3.7/site-packages/jinja2/environment.py", line 1010, in get_template
    return self._load_template(name, globals)
  File "/home/airflow/.local/lib/python3.7/site-packages/jinja2/environment.py", line 969, in _load_template
    template = self.loader.load(self, name, self.make_globals(globals))
  File "/home/airflow/.local/lib/python3.7/site-packages/jinja2/loaders.py", line 126, in load
    source, filename, uptodate = self.get_source(environment, name)
  File "/home/airflow/.local/lib/python3.7/site-packages/jinja2/loaders.py", line 218, in get_source
    raise TemplateNotFound(template)
jinja2.exceptions.TemplateNotFound: create_tables.sql
[2023-03-21T16:00:51.224+0000] {taskinstance.py:1326} INFO - Marking task as FAILED. dag_id=batch_pipeline, task_id=create_tables, execution_date=20230320T000000, start_date=20230321T160050, end_date=20230321T160051
[2023-03-21T16:00:51.253+0000] {standard_task_runner.py:105} ERROR - Failed to execute job 166 for task create_tables (create_tables.sql; 3978)
[2023-03-21T16:00:51.308+0000] {local_task_job.py:212} INFO - Task exited with return code 1
[2023-03-21T16:00:51.387+0000] {taskinstance.py:2585} INFO - 0 downstream tasks scheduled from follow-on schedule check
