[2023-03-21T13:23:00.077+0000] {taskinstance.py:1084} INFO - Dependencies all met for dep_context=non-requeueable deps ti=<TaskInstance: batch_pipeline.create_tables scheduled__2023-03-20T00:00:00+00:00 [queued]>
[2023-03-21T13:23:00.434+0000] {taskinstance.py:1084} INFO - Dependencies all met for dep_context=requeueable deps ti=<TaskInstance: batch_pipeline.create_tables scheduled__2023-03-20T00:00:00+00:00 [queued]>
[2023-03-21T13:23:00.438+0000] {taskinstance.py:1282} INFO - 
--------------------------------------------------------------------------------
[2023-03-21T13:23:00.444+0000] {taskinstance.py:1283} INFO - Starting attempt 6 of 6
[2023-03-21T13:23:00.449+0000] {taskinstance.py:1284} INFO - 
--------------------------------------------------------------------------------
[2023-03-21T13:23:01.098+0000] {taskinstance.py:1303} INFO - Executing <Task(PostgresOperator): create_tables> on 2023-03-20 00:00:00+00:00
[2023-03-21T13:23:01.255+0000] {standard_task_runner.py:55} INFO - Started process 1119 to run task
[2023-03-21T13:23:01.390+0000] {standard_task_runner.py:82} INFO - Running: ['***', 'tasks', 'run', 'batch_pipeline', 'create_tables', 'scheduled__2023-03-20T00:00:00+00:00', '--job-id', '45', '--raw', '--subdir', 'DAGS_FOLDER/batch_pipeline.py', '--cfg-path', '/tmp/tmpn21_qk75']
[2023-03-21T13:23:01.423+0000] {standard_task_runner.py:83} INFO - Job 45: Subtask create_tables
[2023-03-21T13:23:02.822+0000] {task_command.py:388} INFO - Running <TaskInstance: batch_pipeline.create_tables scheduled__2023-03-20T00:00:00+00:00 [running]> on host 070f7bf9e1a1
[2023-03-21T13:23:03.304+0000] {abstractoperator.py:615} ERROR - Exception rendering Jinja template for task 'create_tables', field 'sql'. Template: 'create_tables.sql'
Traceback (most recent call last):
  File "/home/airflow/.local/lib/python3.7/site-packages/airflow/models/abstractoperator.py", line 607, in _do_render_template_fields
    seen_oids,
  File "/home/airflow/.local/lib/python3.7/site-packages/airflow/models/abstractoperator.py", line 659, in render_template
    template = jinja_env.get_template(value)
  File "/home/airflow/.local/lib/python3.7/site-packages/jinja2/environment.py", line 1010, in get_template
    return self._load_template(name, globals)
  File "/home/airflow/.local/lib/python3.7/site-packages/jinja2/environment.py", line 969, in _load_template
    template = self.loader.load(self, name, self.make_globals(globals))
  File "/home/airflow/.local/lib/python3.7/site-packages/jinja2/loaders.py", line 126, in load
    source, filename, uptodate = self.get_source(environment, name)
  File "/home/airflow/.local/lib/python3.7/site-packages/jinja2/loaders.py", line 218, in get_source
    raise TemplateNotFound(template)
jinja2.exceptions.TemplateNotFound: create_tables.sql
[2023-03-21T13:23:03.319+0000] {taskinstance.py:1775} ERROR - Task failed with exception
Traceback (most recent call last):
  File "/home/airflow/.local/lib/python3.7/site-packages/airflow/models/taskinstance.py", line 1377, in _run_raw_task
    self._execute_task_with_callbacks(context, test_mode)
  File "/home/airflow/.local/lib/python3.7/site-packages/airflow/models/taskinstance.py", line 1495, in _execute_task_with_callbacks
    task_orig = self.render_templates(context=context)
  File "/home/airflow/.local/lib/python3.7/site-packages/airflow/models/taskinstance.py", line 2122, in render_templates
    original_task.render_template_fields(context)
  File "/home/airflow/.local/lib/python3.7/site-packages/airflow/models/baseoperator.py", line 1179, in render_template_fields
    self._do_render_template_fields(self, self.template_fields, context, jinja_env, set())
  File "/home/airflow/.local/lib/python3.7/site-packages/airflow/utils/session.py", line 75, in wrapper
    return func(*args, session=session, **kwargs)
  File "/home/airflow/.local/lib/python3.7/site-packages/airflow/models/abstractoperator.py", line 607, in _do_render_template_fields
    seen_oids,
  File "/home/airflow/.local/lib/python3.7/site-packages/airflow/models/abstractoperator.py", line 659, in render_template
    template = jinja_env.get_template(value)
  File "/home/airflow/.local/lib/python3.7/site-packages/jinja2/environment.py", line 1010, in get_template
    return self._load_template(name, globals)
  File "/home/airflow/.local/lib/python3.7/site-packages/jinja2/environment.py", line 969, in _load_template
    template = self.loader.load(self, name, self.make_globals(globals))
  File "/home/airflow/.local/lib/python3.7/site-packages/jinja2/loaders.py", line 126, in load
    source, filename, uptodate = self.get_source(environment, name)
  File "/home/airflow/.local/lib/python3.7/site-packages/jinja2/loaders.py", line 218, in get_source
    raise TemplateNotFound(template)
jinja2.exceptions.TemplateNotFound: create_tables.sql
[2023-03-21T13:23:03.375+0000] {taskinstance.py:1326} INFO - Marking task as FAILED. dag_id=batch_pipeline, task_id=create_tables, execution_date=20230320T000000, start_date=20230321T132300, end_date=20230321T132303
[2023-03-21T13:23:03.447+0000] {standard_task_runner.py:105} ERROR - Failed to execute job 45 for task create_tables (create_tables.sql; 1119)
[2023-03-21T13:23:03.536+0000] {local_task_job.py:212} INFO - Task exited with return code 1
[2023-03-21T13:23:03.741+0000] {taskinstance.py:2585} INFO - 0 downstream tasks scheduled from follow-on schedule check
[2023-03-21T15:39:44.023+0000] {taskinstance.py:1084} INFO - Dependencies all met for dep_context=non-requeueable deps ti=<TaskInstance: batch_pipeline.create_tables scheduled__2023-03-20T00:00:00+00:00 [queued]>
[2023-03-21T15:39:44.071+0000] {taskinstance.py:1084} INFO - Dependencies all met for dep_context=requeueable deps ti=<TaskInstance: batch_pipeline.create_tables scheduled__2023-03-20T00:00:00+00:00 [queued]>
[2023-03-21T15:39:44.073+0000] {taskinstance.py:1282} INFO - 
--------------------------------------------------------------------------------
[2023-03-21T15:39:44.085+0000] {taskinstance.py:1283} INFO - Starting attempt 6 of 6
[2023-03-21T15:39:44.091+0000] {taskinstance.py:1284} INFO - 
--------------------------------------------------------------------------------
[2023-03-21T15:39:44.146+0000] {taskinstance.py:1303} INFO - Executing <Task(PostgresOperator): create_tables> on 2023-03-20 00:00:00+00:00
[2023-03-21T15:39:44.173+0000] {standard_task_runner.py:55} INFO - Started process 3588 to run task
[2023-03-21T15:39:44.195+0000] {standard_task_runner.py:82} INFO - Running: ['***', 'tasks', 'run', 'batch_pipeline', 'create_tables', 'scheduled__2023-03-20T00:00:00+00:00', '--job-id', '139', '--raw', '--subdir', 'DAGS_FOLDER/batch_pipeline.py', '--cfg-path', '/tmp/tmp7fs44km_']
[2023-03-21T15:39:44.210+0000] {standard_task_runner.py:83} INFO - Job 139: Subtask create_tables
[2023-03-21T15:39:44.476+0000] {task_command.py:388} INFO - Running <TaskInstance: batch_pipeline.create_tables scheduled__2023-03-20T00:00:00+00:00 [running]> on host 070f7bf9e1a1
[2023-03-21T15:39:44.600+0000] {abstractoperator.py:615} ERROR - Exception rendering Jinja template for task 'create_tables', field 'sql'. Template: 'create_tables.sql'
Traceback (most recent call last):
  File "/home/airflow/.local/lib/python3.7/site-packages/airflow/models/abstractoperator.py", line 607, in _do_render_template_fields
    seen_oids,
  File "/home/airflow/.local/lib/python3.7/site-packages/airflow/models/abstractoperator.py", line 659, in render_template
    template = jinja_env.get_template(value)
  File "/home/airflow/.local/lib/python3.7/site-packages/jinja2/environment.py", line 1010, in get_template
    return self._load_template(name, globals)
  File "/home/airflow/.local/lib/python3.7/site-packages/jinja2/environment.py", line 969, in _load_template
    template = self.loader.load(self, name, self.make_globals(globals))
  File "/home/airflow/.local/lib/python3.7/site-packages/jinja2/loaders.py", line 126, in load
    source, filename, uptodate = self.get_source(environment, name)
  File "/home/airflow/.local/lib/python3.7/site-packages/jinja2/loaders.py", line 218, in get_source
    raise TemplateNotFound(template)
jinja2.exceptions.TemplateNotFound: create_tables.sql
[2023-03-21T15:39:44.606+0000] {taskinstance.py:1775} ERROR - Task failed with exception
Traceback (most recent call last):
  File "/home/airflow/.local/lib/python3.7/site-packages/airflow/models/taskinstance.py", line 1377, in _run_raw_task
    self._execute_task_with_callbacks(context, test_mode)
  File "/home/airflow/.local/lib/python3.7/site-packages/airflow/models/taskinstance.py", line 1495, in _execute_task_with_callbacks
    task_orig = self.render_templates(context=context)
  File "/home/airflow/.local/lib/python3.7/site-packages/airflow/models/taskinstance.py", line 2122, in render_templates
    original_task.render_template_fields(context)
  File "/home/airflow/.local/lib/python3.7/site-packages/airflow/models/baseoperator.py", line 1179, in render_template_fields
    self._do_render_template_fields(self, self.template_fields, context, jinja_env, set())
  File "/home/airflow/.local/lib/python3.7/site-packages/airflow/utils/session.py", line 75, in wrapper
    return func(*args, session=session, **kwargs)
  File "/home/airflow/.local/lib/python3.7/site-packages/airflow/models/abstractoperator.py", line 607, in _do_render_template_fields
    seen_oids,
  File "/home/airflow/.local/lib/python3.7/site-packages/airflow/models/abstractoperator.py", line 659, in render_template
    template = jinja_env.get_template(value)
  File "/home/airflow/.local/lib/python3.7/site-packages/jinja2/environment.py", line 1010, in get_template
    return self._load_template(name, globals)
  File "/home/airflow/.local/lib/python3.7/site-packages/jinja2/environment.py", line 969, in _load_template
    template = self.loader.load(self, name, self.make_globals(globals))
  File "/home/airflow/.local/lib/python3.7/site-packages/jinja2/loaders.py", line 126, in load
    source, filename, uptodate = self.get_source(environment, name)
  File "/home/airflow/.local/lib/python3.7/site-packages/jinja2/loaders.py", line 218, in get_source
    raise TemplateNotFound(template)
jinja2.exceptions.TemplateNotFound: create_tables.sql
[2023-03-21T15:39:44.638+0000] {taskinstance.py:1326} INFO - Marking task as FAILED. dag_id=batch_pipeline, task_id=create_tables, execution_date=20230320T000000, start_date=20230321T153944, end_date=20230321T153944
[2023-03-21T15:39:44.674+0000] {standard_task_runner.py:105} ERROR - Failed to execute job 139 for task create_tables (create_tables.sql; 3588)
[2023-03-21T15:39:44.714+0000] {local_task_job.py:212} INFO - Task exited with return code 1
[2023-03-21T15:39:44.843+0000] {taskinstance.py:2585} INFO - 0 downstream tasks scheduled from follow-on schedule check
