[2023-03-21T12:53:00.034+0000] {taskinstance.py:1084} INFO - Dependencies all met for dep_context=non-requeueable deps ti=<TaskInstance: batch_pipeline.extract_database_tables scheduled__2023-03-20T00:00:00+00:00 [queued]>
[2023-03-21T12:53:00.081+0000] {taskinstance.py:1084} INFO - Dependencies all met for dep_context=requeueable deps ti=<TaskInstance: batch_pipeline.extract_database_tables scheduled__2023-03-20T00:00:00+00:00 [queued]>
[2023-03-21T12:53:00.104+0000] {taskinstance.py:1282} INFO - 
--------------------------------------------------------------------------------
[2023-03-21T12:53:00.106+0000] {taskinstance.py:1283} INFO - Starting attempt 2 of 2
[2023-03-21T12:53:00.108+0000] {taskinstance.py:1284} INFO - 
--------------------------------------------------------------------------------
[2023-03-21T12:53:00.180+0000] {taskinstance.py:1303} INFO - Executing <Task(PythonOperator): extract_database_tables> on 2023-03-20 00:00:00+00:00
[2023-03-21T12:53:00.210+0000] {standard_task_runner.py:55} INFO - Started process 557 to run task
[2023-03-21T12:53:00.248+0000] {standard_task_runner.py:82} INFO - Running: ['***', 'tasks', 'run', 'batch_pipeline', 'extract_database_tables', 'scheduled__2023-03-20T00:00:00+00:00', '--job-id', '17', '--raw', '--subdir', 'DAGS_FOLDER/batch_pipeline.py', '--cfg-path', '/tmp/tmpic1hc8bu']
[2023-03-21T12:53:00.250+0000] {standard_task_runner.py:83} INFO - Job 17: Subtask extract_database_tables
[2023-03-21T12:53:00.629+0000] {task_command.py:388} INFO - Running <TaskInstance: batch_pipeline.extract_database_tables scheduled__2023-03-20T00:00:00+00:00 [running]> on host 070f7bf9e1a1
[2023-03-21T12:53:01.015+0000] {taskinstance.py:1511} INFO - Exporting the following env vars:
AIRFLOW_CTX_DAG_OWNER=Pedrosa
AIRFLOW_CTX_DAG_ID=batch_pipeline
AIRFLOW_CTX_TASK_ID=extract_database_tables
AIRFLOW_CTX_EXECUTION_DATE=2023-03-20T00:00:00+00:00
AIRFLOW_CTX_TRY_NUMBER=2
AIRFLOW_CTX_DAG_RUN_ID=scheduled__2023-03-20T00:00:00+00:00
[2023-03-21T12:53:01.083+0000] {logging_mixin.py:137} INFO - Erro: (psycopg2.OperationalError) connection to server at "host.docker.internal" (192.168.65.2), port 5432 failed: FATAL:  password authentication failed for user "postgres"

(Background on this error at: https://sqlalche.me/e/14/e3q8)
[2023-03-21T12:53:01.086+0000] {python.py:177} INFO - Done. Returned value was: None
[2023-03-21T12:53:01.119+0000] {taskinstance.py:1326} INFO - Marking task as SUCCESS. dag_id=batch_pipeline, task_id=extract_database_tables, execution_date=20230320T000000, start_date=20230321T125300, end_date=20230321T125301
[2023-03-21T12:53:01.271+0000] {local_task_job.py:212} INFO - Task exited with return code 0
[2023-03-21T12:53:01.433+0000] {taskinstance.py:2585} INFO - 1 downstream tasks scheduled from follow-on schedule check
[2023-03-21T13:42:54.363+0000] {taskinstance.py:1084} INFO - Dependencies all met for dep_context=non-requeueable deps ti=<TaskInstance: batch_pipeline.extract_database_tables scheduled__2023-03-20T00:00:00+00:00 [queued]>
[2023-03-21T13:42:54.390+0000] {taskinstance.py:1084} INFO - Dependencies all met for dep_context=requeueable deps ti=<TaskInstance: batch_pipeline.extract_database_tables scheduled__2023-03-20T00:00:00+00:00 [queued]>
[2023-03-21T13:42:54.395+0000] {taskinstance.py:1282} INFO - 
--------------------------------------------------------------------------------
[2023-03-21T13:42:54.398+0000] {taskinstance.py:1283} INFO - Starting attempt 2 of 2
[2023-03-21T13:42:54.400+0000] {taskinstance.py:1284} INFO - 
--------------------------------------------------------------------------------
[2023-03-21T13:42:54.436+0000] {taskinstance.py:1303} INFO - Executing <Task(PythonOperator): extract_database_tables> on 2023-03-20 00:00:00+00:00
[2023-03-21T13:42:54.457+0000] {standard_task_runner.py:55} INFO - Started process 1561 to run task
[2023-03-21T13:42:54.476+0000] {standard_task_runner.py:82} INFO - Running: ['***', 'tasks', 'run', 'batch_pipeline', 'extract_database_tables', 'scheduled__2023-03-20T00:00:00+00:00', '--job-id', '87', '--raw', '--subdir', 'DAGS_FOLDER/batch_pipeline.py', '--cfg-path', '/tmp/tmp70opmszh']
[2023-03-21T13:42:54.486+0000] {standard_task_runner.py:83} INFO - Job 87: Subtask extract_database_tables
[2023-03-21T13:42:54.668+0000] {task_command.py:388} INFO - Running <TaskInstance: batch_pipeline.extract_database_tables scheduled__2023-03-20T00:00:00+00:00 [running]> on host 070f7bf9e1a1
[2023-03-21T13:42:54.800+0000] {taskinstance.py:1511} INFO - Exporting the following env vars:
AIRFLOW_CTX_DAG_OWNER=Pedrosa
AIRFLOW_CTX_DAG_ID=batch_pipeline
AIRFLOW_CTX_TASK_ID=extract_database_tables
AIRFLOW_CTX_EXECUTION_DATE=2023-03-20T00:00:00+00:00
AIRFLOW_CTX_TRY_NUMBER=2
AIRFLOW_CTX_DAG_RUN_ID=scheduled__2023-03-20T00:00:00+00:00
[2023-03-21T13:42:54.835+0000] {logging_mixin.py:137} INFO - Erro: (psycopg2.OperationalError) connection to server at "host.docker.internal" (192.168.65.2), port 5432 failed: FATAL:  password authentication failed for user "postgres"

(Background on this error at: https://sqlalche.me/e/14/e3q8)
[2023-03-21T13:42:54.838+0000] {python.py:177} INFO - Done. Returned value was: None
[2023-03-21T13:42:54.857+0000] {taskinstance.py:1326} INFO - Marking task as SUCCESS. dag_id=batch_pipeline, task_id=extract_database_tables, execution_date=20230320T000000, start_date=20230321T134254, end_date=20230321T134254
[2023-03-21T13:42:54.899+0000] {local_task_job.py:212} INFO - Task exited with return code 0
[2023-03-21T13:42:54.950+0000] {taskinstance.py:2585} INFO - 1 downstream tasks scheduled from follow-on schedule check
[2023-03-21T13:59:38.614+0000] {taskinstance.py:1084} INFO - Dependencies all met for dep_context=non-requeueable deps ti=<TaskInstance: batch_pipeline.extract_database_tables scheduled__2023-03-20T00:00:00+00:00 [queued]>
[2023-03-21T13:59:38.665+0000] {taskinstance.py:1084} INFO - Dependencies all met for dep_context=requeueable deps ti=<TaskInstance: batch_pipeline.extract_database_tables scheduled__2023-03-20T00:00:00+00:00 [queued]>
[2023-03-21T13:59:38.667+0000] {taskinstance.py:1282} INFO - 
--------------------------------------------------------------------------------
[2023-03-21T13:59:38.670+0000] {taskinstance.py:1283} INFO - Starting attempt 2 of 2
[2023-03-21T13:59:38.672+0000] {taskinstance.py:1284} INFO - 
--------------------------------------------------------------------------------
[2023-03-21T13:59:38.724+0000] {taskinstance.py:1303} INFO - Executing <Task(PythonOperator): extract_database_tables> on 2023-03-20 00:00:00+00:00
[2023-03-21T13:59:38.752+0000] {standard_task_runner.py:55} INFO - Started process 1877 to run task
[2023-03-21T13:59:38.781+0000] {standard_task_runner.py:82} INFO - Running: ['***', 'tasks', 'run', 'batch_pipeline', 'extract_database_tables', 'scheduled__2023-03-20T00:00:00+00:00', '--job-id', '99', '--raw', '--subdir', 'DAGS_FOLDER/load_csv.py', '--cfg-path', '/tmp/tmph6nnh9r3']
[2023-03-21T13:59:38.788+0000] {standard_task_runner.py:83} INFO - Job 99: Subtask extract_database_tables
[2023-03-21T13:59:39.193+0000] {task_command.py:388} INFO - Running <TaskInstance: batch_pipeline.extract_database_tables scheduled__2023-03-20T00:00:00+00:00 [running]> on host 070f7bf9e1a1
[2023-03-21T13:59:39.617+0000] {taskinstance.py:1511} INFO - Exporting the following env vars:
AIRFLOW_CTX_DAG_OWNER=Pedrosa
AIRFLOW_CTX_DAG_ID=batch_pipeline
AIRFLOW_CTX_TASK_ID=extract_database_tables
AIRFLOW_CTX_EXECUTION_DATE=2023-03-20T00:00:00+00:00
AIRFLOW_CTX_TRY_NUMBER=2
AIRFLOW_CTX_DAG_RUN_ID=scheduled__2023-03-20T00:00:00+00:00
[2023-03-21T13:59:39.659+0000] {logging_mixin.py:137} INFO - Erro: (psycopg2.OperationalError) connection to server at "host.docker.internal" (192.168.65.2), port 5432 failed: FATAL:  password authentication failed for user "postgres"

(Background on this error at: https://sqlalche.me/e/14/e3q8)
[2023-03-21T13:59:39.661+0000] {python.py:177} INFO - Done. Returned value was: None
[2023-03-21T13:59:39.711+0000] {taskinstance.py:1326} INFO - Marking task as SUCCESS. dag_id=batch_pipeline, task_id=extract_database_tables, execution_date=20230320T000000, start_date=20230321T135938, end_date=20230321T135939
[2023-03-21T13:59:39.829+0000] {local_task_job.py:212} INFO - Task exited with return code 0
[2023-03-21T13:59:39.980+0000] {taskinstance.py:2585} INFO - 1 downstream tasks scheduled from follow-on schedule check
[2023-03-21T15:16:14.311+0000] {taskinstance.py:1084} INFO - Dependencies all met for dep_context=non-requeueable deps ti=<TaskInstance: batch_pipeline.extract_database_tables scheduled__2023-03-20T00:00:00+00:00 [queued]>
[2023-03-21T15:16:14.341+0000] {taskinstance.py:1084} INFO - Dependencies all met for dep_context=requeueable deps ti=<TaskInstance: batch_pipeline.extract_database_tables scheduled__2023-03-20T00:00:00+00:00 [queued]>
[2023-03-21T15:16:14.343+0000] {taskinstance.py:1282} INFO - 
--------------------------------------------------------------------------------
[2023-03-21T15:16:14.349+0000] {taskinstance.py:1283} INFO - Starting attempt 2 of 2
[2023-03-21T15:16:14.352+0000] {taskinstance.py:1284} INFO - 
--------------------------------------------------------------------------------
[2023-03-21T15:16:14.398+0000] {taskinstance.py:1303} INFO - Executing <Task(PythonOperator): extract_database_tables> on 2023-03-20 00:00:00+00:00
[2023-03-21T15:16:14.417+0000] {standard_task_runner.py:55} INFO - Started process 3145 to run task
[2023-03-21T15:16:14.435+0000] {standard_task_runner.py:82} INFO - Running: ['***', 'tasks', 'run', 'batch_pipeline', 'extract_database_tables', 'scheduled__2023-03-20T00:00:00+00:00', '--job-id', '114', '--raw', '--subdir', 'DAGS_FOLDER/batch_pipeline.py', '--cfg-path', '/tmp/tmp23icdj7f']
[2023-03-21T15:16:14.438+0000] {standard_task_runner.py:83} INFO - Job 114: Subtask extract_database_tables
[2023-03-21T15:16:14.646+0000] {task_command.py:388} INFO - Running <TaskInstance: batch_pipeline.extract_database_tables scheduled__2023-03-20T00:00:00+00:00 [running]> on host 070f7bf9e1a1
[2023-03-21T15:16:14.781+0000] {taskinstance.py:1511} INFO - Exporting the following env vars:
AIRFLOW_CTX_DAG_OWNER=Pedrosa
AIRFLOW_CTX_DAG_ID=batch_pipeline
AIRFLOW_CTX_TASK_ID=extract_database_tables
AIRFLOW_CTX_EXECUTION_DATE=2023-03-20T00:00:00+00:00
AIRFLOW_CTX_TRY_NUMBER=2
AIRFLOW_CTX_DAG_RUN_ID=scheduled__2023-03-20T00:00:00+00:00
[2023-03-21T15:16:14.788+0000] {logging_mixin.py:137} INFO - Erro: (psycopg2.OperationalError) connection to server at "localhost" (127.0.0.1), port 5432 failed: Connection refused
	Is the server running on that host and accepting TCP/IP connections?
connection to server at "localhost" (::1), port 5432 failed: Cannot assign requested address
	Is the server running on that host and accepting TCP/IP connections?

(Background on this error at: https://sqlalche.me/e/14/e3q8)
[2023-03-21T15:16:14.790+0000] {python.py:177} INFO - Done. Returned value was: None
[2023-03-21T15:16:14.813+0000] {taskinstance.py:1326} INFO - Marking task as SUCCESS. dag_id=batch_pipeline, task_id=extract_database_tables, execution_date=20230320T000000, start_date=20230321T151614, end_date=20230321T151614
[2023-03-21T15:16:14.891+0000] {local_task_job.py:212} INFO - Task exited with return code 0
[2023-03-21T15:16:14.990+0000] {taskinstance.py:2585} INFO - 0 downstream tasks scheduled from follow-on schedule check
[2023-03-21T15:25:25.797+0000] {taskinstance.py:1084} INFO - Dependencies all met for dep_context=non-requeueable deps ti=<TaskInstance: batch_pipeline.extract_database_tables scheduled__2023-03-20T00:00:00+00:00 [queued]>
[2023-03-21T15:25:25.830+0000] {taskinstance.py:1084} INFO - Dependencies all met for dep_context=requeueable deps ti=<TaskInstance: batch_pipeline.extract_database_tables scheduled__2023-03-20T00:00:00+00:00 [queued]>
[2023-03-21T15:25:25.837+0000] {taskinstance.py:1282} INFO - 
--------------------------------------------------------------------------------
[2023-03-21T15:25:25.839+0000] {taskinstance.py:1283} INFO - Starting attempt 2 of 2
[2023-03-21T15:25:25.842+0000] {taskinstance.py:1284} INFO - 
--------------------------------------------------------------------------------
[2023-03-21T15:25:25.887+0000] {taskinstance.py:1303} INFO - Executing <Task(PythonOperator): extract_database_tables> on 2023-03-20 00:00:00+00:00
[2023-03-21T15:25:25.906+0000] {standard_task_runner.py:55} INFO - Started process 3320 to run task
[2023-03-21T15:25:25.931+0000] {standard_task_runner.py:82} INFO - Running: ['***', 'tasks', 'run', 'batch_pipeline', 'extract_database_tables', 'scheduled__2023-03-20T00:00:00+00:00', '--job-id', '126', '--raw', '--subdir', 'DAGS_FOLDER/batch_pipeline.py', '--cfg-path', '/tmp/tmp37skqkde']
[2023-03-21T15:25:25.934+0000] {standard_task_runner.py:83} INFO - Job 126: Subtask extract_database_tables
[2023-03-21T15:25:26.160+0000] {task_command.py:388} INFO - Running <TaskInstance: batch_pipeline.extract_database_tables scheduled__2023-03-20T00:00:00+00:00 [running]> on host 070f7bf9e1a1
[2023-03-21T15:25:26.382+0000] {taskinstance.py:1511} INFO - Exporting the following env vars:
AIRFLOW_CTX_DAG_OWNER=Pedrosa
AIRFLOW_CTX_DAG_ID=batch_pipeline
AIRFLOW_CTX_TASK_ID=extract_database_tables
AIRFLOW_CTX_EXECUTION_DATE=2023-03-20T00:00:00+00:00
AIRFLOW_CTX_TRY_NUMBER=2
AIRFLOW_CTX_DAG_RUN_ID=scheduled__2023-03-20T00:00:00+00:00
[2023-03-21T15:25:26.395+0000] {logging_mixin.py:137} INFO - Erro: (psycopg2.OperationalError) connection to server at "localhost" (127.0.0.1), port 5432 failed: Connection refused
	Is the server running on that host and accepting TCP/IP connections?
connection to server at "localhost" (::1), port 5432 failed: Cannot assign requested address
	Is the server running on that host and accepting TCP/IP connections?

(Background on this error at: https://sqlalche.me/e/14/e3q8)
[2023-03-21T15:25:26.397+0000] {python.py:177} INFO - Done. Returned value was: None
[2023-03-21T15:25:26.438+0000] {taskinstance.py:1326} INFO - Marking task as SUCCESS. dag_id=batch_pipeline, task_id=extract_database_tables, execution_date=20230320T000000, start_date=20230321T152525, end_date=20230321T152526
[2023-03-21T15:25:26.525+0000] {local_task_job.py:212} INFO - Task exited with return code 0
[2023-03-21T15:25:26.599+0000] {taskinstance.py:2585} INFO - 1 downstream tasks scheduled from follow-on schedule check
[2023-03-21T15:49:22.086+0000] {taskinstance.py:1084} INFO - Dependencies all met for dep_context=non-requeueable deps ti=<TaskInstance: batch_pipeline.extract_database_tables scheduled__2023-03-20T00:00:00+00:00 [queued]>
[2023-03-21T15:49:22.115+0000] {taskinstance.py:1084} INFO - Dependencies all met for dep_context=requeueable deps ti=<TaskInstance: batch_pipeline.extract_database_tables scheduled__2023-03-20T00:00:00+00:00 [queued]>
[2023-03-21T15:49:22.117+0000] {taskinstance.py:1282} INFO - 
--------------------------------------------------------------------------------
[2023-03-21T15:49:22.120+0000] {taskinstance.py:1283} INFO - Starting attempt 2 of 2
[2023-03-21T15:49:22.123+0000] {taskinstance.py:1284} INFO - 
--------------------------------------------------------------------------------
[2023-03-21T15:49:22.171+0000] {taskinstance.py:1303} INFO - Executing <Task(PythonOperator): extract_database_tables> on 2023-03-20 00:00:00+00:00
[2023-03-21T15:49:22.187+0000] {standard_task_runner.py:55} INFO - Started process 3763 to run task
[2023-03-21T15:49:22.207+0000] {standard_task_runner.py:82} INFO - Running: ['***', 'tasks', 'run', 'batch_pipeline', 'extract_database_tables', 'scheduled__2023-03-20T00:00:00+00:00', '--job-id', '150', '--raw', '--subdir', 'DAGS_FOLDER/batch_pipeline.py', '--cfg-path', '/tmp/tmpkip1gdbj']
[2023-03-21T15:49:22.210+0000] {standard_task_runner.py:83} INFO - Job 150: Subtask extract_database_tables
[2023-03-21T15:49:22.373+0000] {task_command.py:388} INFO - Running <TaskInstance: batch_pipeline.extract_database_tables scheduled__2023-03-20T00:00:00+00:00 [running]> on host 070f7bf9e1a1
[2023-03-21T15:49:22.935+0000] {taskinstance.py:1511} INFO - Exporting the following env vars:
AIRFLOW_CTX_DAG_OWNER=Pedrosa
AIRFLOW_CTX_DAG_ID=batch_pipeline
AIRFLOW_CTX_TASK_ID=extract_database_tables
AIRFLOW_CTX_EXECUTION_DATE=2023-03-20T00:00:00+00:00
AIRFLOW_CTX_TRY_NUMBER=2
AIRFLOW_CTX_DAG_RUN_ID=scheduled__2023-03-20T00:00:00+00:00
[2023-03-21T15:49:22.980+0000] {logging_mixin.py:137} INFO - Erro: (psycopg2.errors.UndefinedTable) relation "categories" does not exist
LINE 1: select * from categories;
                      ^

[SQL: select * from categories;]
(Background on this error at: https://sqlalche.me/e/14/f405)
[2023-03-21T15:49:22.983+0000] {python.py:177} INFO - Done. Returned value was: None
[2023-03-21T15:49:23.013+0000] {taskinstance.py:1326} INFO - Marking task as SUCCESS. dag_id=batch_pipeline, task_id=extract_database_tables, execution_date=20230320T000000, start_date=20230321T154922, end_date=20230321T154923
[2023-03-21T15:49:23.068+0000] {local_task_job.py:212} INFO - Task exited with return code 0
[2023-03-21T15:49:23.132+0000] {taskinstance.py:2585} INFO - 1 downstream tasks scheduled from follow-on schedule check
[2023-03-21T16:00:46.900+0000] {taskinstance.py:1084} INFO - Dependencies all met for dep_context=non-requeueable deps ti=<TaskInstance: batch_pipeline.extract_database_tables scheduled__2023-03-20T00:00:00+00:00 [queued]>
[2023-03-21T16:00:46.951+0000] {taskinstance.py:1084} INFO - Dependencies all met for dep_context=requeueable deps ti=<TaskInstance: batch_pipeline.extract_database_tables scheduled__2023-03-20T00:00:00+00:00 [queued]>
[2023-03-21T16:00:46.961+0000] {taskinstance.py:1282} INFO - 
--------------------------------------------------------------------------------
[2023-03-21T16:00:46.967+0000] {taskinstance.py:1283} INFO - Starting attempt 2 of 2
[2023-03-21T16:00:46.969+0000] {taskinstance.py:1284} INFO - 
--------------------------------------------------------------------------------
[2023-03-21T16:00:47.018+0000] {taskinstance.py:1303} INFO - Executing <Task(PythonOperator): extract_database_tables> on 2023-03-20 00:00:00+00:00
[2023-03-21T16:00:47.038+0000] {standard_task_runner.py:55} INFO - Started process 3975 to run task
[2023-03-21T16:00:47.052+0000] {standard_task_runner.py:82} INFO - Running: ['***', 'tasks', 'run', 'batch_pipeline', 'extract_database_tables', 'scheduled__2023-03-20T00:00:00+00:00', '--job-id', '165', '--raw', '--subdir', 'DAGS_FOLDER/batch_pipeline.py', '--cfg-path', '/tmp/tmpg8iplnj4']
[2023-03-21T16:00:47.055+0000] {standard_task_runner.py:83} INFO - Job 165: Subtask extract_database_tables
[2023-03-21T16:00:47.266+0000] {task_command.py:388} INFO - Running <TaskInstance: batch_pipeline.extract_database_tables scheduled__2023-03-20T00:00:00+00:00 [running]> on host 070f7bf9e1a1
[2023-03-21T16:00:47.479+0000] {taskinstance.py:1511} INFO - Exporting the following env vars:
AIRFLOW_CTX_DAG_OWNER=Pedrosa
AIRFLOW_CTX_DAG_ID=batch_pipeline
AIRFLOW_CTX_TASK_ID=extract_database_tables
AIRFLOW_CTX_EXECUTION_DATE=2023-03-20T00:00:00+00:00
AIRFLOW_CTX_TRY_NUMBER=2
AIRFLOW_CTX_DAG_RUN_ID=scheduled__2023-03-20T00:00:00+00:00
[2023-03-21T16:00:47.520+0000] {logging_mixin.py:137} INFO - Erro: (psycopg2.errors.UndefinedTable) relation "orders" does not exist
LINE 1: select * from orders;
                      ^

[SQL: select * from orders;]
(Background on this error at: https://sqlalche.me/e/14/f405)
[2023-03-21T16:00:47.522+0000] {python.py:177} INFO - Done. Returned value was: None
[2023-03-21T16:00:47.559+0000] {taskinstance.py:1326} INFO - Marking task as SUCCESS. dag_id=batch_pipeline, task_id=extract_database_tables, execution_date=20230320T000000, start_date=20230321T160046, end_date=20230321T160047
[2023-03-21T16:00:47.636+0000] {local_task_job.py:212} INFO - Task exited with return code 0
[2023-03-21T16:00:47.712+0000] {taskinstance.py:2585} INFO - 1 downstream tasks scheduled from follow-on schedule check
