[2023-03-21T13:11:51.345+0000] {taskinstance.py:1084} INFO - Dependencies all met for dep_context=non-requeueable deps ti=<TaskInstance: batch_pipeline.extract_database_tables scheduled__2023-03-20T00:00:00+00:00 [queued]>
[2023-03-21T13:11:51.428+0000] {taskinstance.py:1084} INFO - Dependencies all met for dep_context=requeueable deps ti=<TaskInstance: batch_pipeline.extract_database_tables scheduled__2023-03-20T00:00:00+00:00 [queued]>
[2023-03-21T13:11:51.432+0000] {taskinstance.py:1282} INFO - 
--------------------------------------------------------------------------------
[2023-03-21T13:11:51.434+0000] {taskinstance.py:1283} INFO - Starting attempt 3 of 3
[2023-03-21T13:11:51.435+0000] {taskinstance.py:1284} INFO - 
--------------------------------------------------------------------------------
[2023-03-21T13:11:51.618+0000] {taskinstance.py:1303} INFO - Executing <Task(PythonOperator): extract_database_tables> on 2023-03-20 00:00:00+00:00
[2023-03-21T13:11:51.745+0000] {standard_task_runner.py:55} INFO - Started process 879 to run task
[2023-03-21T13:11:51.818+0000] {standard_task_runner.py:82} INFO - Running: ['***', 'tasks', 'run', 'batch_pipeline', 'extract_database_tables', 'scheduled__2023-03-20T00:00:00+00:00', '--job-id', '24', '--raw', '--subdir', 'DAGS_FOLDER/batch_pipeline.py', '--cfg-path', '/tmp/tmp31yky_3h']
[2023-03-21T13:11:51.830+0000] {standard_task_runner.py:83} INFO - Job 24: Subtask extract_database_tables
[2023-03-21T13:11:53.446+0000] {task_command.py:388} INFO - Running <TaskInstance: batch_pipeline.extract_database_tables scheduled__2023-03-20T00:00:00+00:00 [running]> on host 070f7bf9e1a1
[2023-03-21T13:11:56.064+0000] {taskinstance.py:1511} INFO - Exporting the following env vars:
AIRFLOW_CTX_DAG_OWNER=Pedrosa
AIRFLOW_CTX_DAG_ID=batch_pipeline
AIRFLOW_CTX_TASK_ID=extract_database_tables
AIRFLOW_CTX_EXECUTION_DATE=2023-03-20T00:00:00+00:00
AIRFLOW_CTX_TRY_NUMBER=3
AIRFLOW_CTX_DAG_RUN_ID=scheduled__2023-03-20T00:00:00+00:00
[2023-03-21T13:11:56.186+0000] {logging_mixin.py:137} INFO - Erro: (psycopg2.OperationalError) connection to server at "host.docker.internal" (192.168.65.2), port 5432 failed: FATAL:  password authentication failed for user "postgres"

(Background on this error at: https://sqlalche.me/e/14/e3q8)
[2023-03-21T13:11:56.191+0000] {python.py:177} INFO - Done. Returned value was: None
[2023-03-21T13:11:56.345+0000] {taskinstance.py:1326} INFO - Marking task as SUCCESS. dag_id=batch_pipeline, task_id=extract_database_tables, execution_date=20230320T000000, start_date=20230321T131151, end_date=20230321T131156
[2023-03-21T13:11:56.597+0000] {local_task_job.py:212} INFO - Task exited with return code 0
[2023-03-21T13:11:57.138+0000] {taskinstance.py:2585} INFO - 1 downstream tasks scheduled from follow-on schedule check
[2023-03-21T13:44:54.984+0000] {taskinstance.py:1084} INFO - Dependencies all met for dep_context=non-requeueable deps ti=<TaskInstance: batch_pipeline.extract_database_tables scheduled__2023-03-20T00:00:00+00:00 [queued]>
[2023-03-21T13:44:55.030+0000] {taskinstance.py:1084} INFO - Dependencies all met for dep_context=requeueable deps ti=<TaskInstance: batch_pipeline.extract_database_tables scheduled__2023-03-20T00:00:00+00:00 [queued]>
[2023-03-21T13:44:55.033+0000] {taskinstance.py:1282} INFO - 
--------------------------------------------------------------------------------
[2023-03-21T13:44:55.037+0000] {taskinstance.py:1283} INFO - Starting attempt 3 of 3
[2023-03-21T13:44:55.040+0000] {taskinstance.py:1284} INFO - 
--------------------------------------------------------------------------------
[2023-03-21T13:44:55.084+0000] {taskinstance.py:1303} INFO - Executing <Task(PythonOperator): extract_database_tables> on 2023-03-20 00:00:00+00:00
[2023-03-21T13:44:55.101+0000] {standard_task_runner.py:55} INFO - Started process 1601 to run task
[2023-03-21T13:44:55.124+0000] {standard_task_runner.py:82} INFO - Running: ['***', 'tasks', 'run', 'batch_pipeline', 'extract_database_tables', 'scheduled__2023-03-20T00:00:00+00:00', '--job-id', '90', '--raw', '--subdir', 'DAGS_FOLDER/batch_pipeline.py', '--cfg-path', '/tmp/tmp4sltdg_b']
[2023-03-21T13:44:55.129+0000] {standard_task_runner.py:83} INFO - Job 90: Subtask extract_database_tables
[2023-03-21T13:44:55.356+0000] {task_command.py:388} INFO - Running <TaskInstance: batch_pipeline.extract_database_tables scheduled__2023-03-20T00:00:00+00:00 [running]> on host 070f7bf9e1a1
[2023-03-21T13:44:55.563+0000] {taskinstance.py:1511} INFO - Exporting the following env vars:
AIRFLOW_CTX_DAG_OWNER=Pedrosa
AIRFLOW_CTX_DAG_ID=batch_pipeline
AIRFLOW_CTX_TASK_ID=extract_database_tables
AIRFLOW_CTX_EXECUTION_DATE=2023-03-20T00:00:00+00:00
AIRFLOW_CTX_TRY_NUMBER=3
AIRFLOW_CTX_DAG_RUN_ID=scheduled__2023-03-20T00:00:00+00:00
[2023-03-21T13:44:55.606+0000] {logging_mixin.py:137} INFO - Erro: (psycopg2.OperationalError) connection to server at "host.docker.internal" (192.168.65.2), port 5432 failed: FATAL:  password authentication failed for user "postgres"

(Background on this error at: https://sqlalche.me/e/14/e3q8)
[2023-03-21T13:44:55.609+0000] {python.py:177} INFO - Done. Returned value was: None
[2023-03-21T13:44:55.634+0000] {taskinstance.py:1326} INFO - Marking task as SUCCESS. dag_id=batch_pipeline, task_id=extract_database_tables, execution_date=20230320T000000, start_date=20230321T134454, end_date=20230321T134455
[2023-03-21T13:44:55.709+0000] {local_task_job.py:212} INFO - Task exited with return code 0
[2023-03-21T13:44:55.778+0000] {taskinstance.py:2585} INFO - 1 downstream tasks scheduled from follow-on schedule check
[2023-03-21T14:52:42.076+0000] {taskinstance.py:1084} INFO - Dependencies all met for dep_context=non-requeueable deps ti=<TaskInstance: batch_pipeline.extract_database_tables scheduled__2023-03-20T00:00:00+00:00 [queued]>
[2023-03-21T14:52:42.107+0000] {taskinstance.py:1084} INFO - Dependencies all met for dep_context=requeueable deps ti=<TaskInstance: batch_pipeline.extract_database_tables scheduled__2023-03-20T00:00:00+00:00 [queued]>
[2023-03-21T14:52:42.113+0000] {taskinstance.py:1282} INFO - 
--------------------------------------------------------------------------------
[2023-03-21T14:52:42.120+0000] {taskinstance.py:1283} INFO - Starting attempt 3 of 3
[2023-03-21T14:52:42.123+0000] {taskinstance.py:1284} INFO - 
--------------------------------------------------------------------------------
[2023-03-21T14:52:42.170+0000] {taskinstance.py:1303} INFO - Executing <Task(PythonOperator): extract_database_tables> on 2023-03-20 00:00:00+00:00
[2023-03-21T14:52:42.183+0000] {standard_task_runner.py:55} INFO - Started process 2742 to run task
[2023-03-21T14:52:42.203+0000] {standard_task_runner.py:82} INFO - Running: ['***', 'tasks', 'run', 'batch_pipeline', 'extract_database_tables', 'scheduled__2023-03-20T00:00:00+00:00', '--job-id', '102', '--raw', '--subdir', 'DAGS_FOLDER/batch_pipeline.py', '--cfg-path', '/tmp/tmp96wih1zd']
[2023-03-21T14:52:42.205+0000] {standard_task_runner.py:83} INFO - Job 102: Subtask extract_database_tables
[2023-03-21T14:52:42.626+0000] {task_command.py:388} INFO - Running <TaskInstance: batch_pipeline.extract_database_tables scheduled__2023-03-20T00:00:00+00:00 [running]> on host 070f7bf9e1a1
[2023-03-21T14:52:42.770+0000] {taskinstance.py:1511} INFO - Exporting the following env vars:
AIRFLOW_CTX_DAG_OWNER=Pedrosa
AIRFLOW_CTX_DAG_ID=batch_pipeline
AIRFLOW_CTX_TASK_ID=extract_database_tables
AIRFLOW_CTX_EXECUTION_DATE=2023-03-20T00:00:00+00:00
AIRFLOW_CTX_TRY_NUMBER=3
AIRFLOW_CTX_DAG_RUN_ID=scheduled__2023-03-20T00:00:00+00:00
[2023-03-21T14:52:42.787+0000] {logging_mixin.py:137} INFO - Erro: (psycopg2.OperationalError) connection to server at "localhost" (127.0.0.1), port 5432 failed: Connection refused
	Is the server running on that host and accepting TCP/IP connections?
connection to server at "localhost" (::1), port 5432 failed: Cannot assign requested address
	Is the server running on that host and accepting TCP/IP connections?

(Background on this error at: https://sqlalche.me/e/14/e3q8)
[2023-03-21T14:52:42.789+0000] {python.py:177} INFO - Done. Returned value was: None
[2023-03-21T14:52:42.808+0000] {taskinstance.py:1326} INFO - Marking task as SUCCESS. dag_id=batch_pipeline, task_id=extract_database_tables, execution_date=20230320T000000, start_date=20230321T145242, end_date=20230321T145242
[2023-03-21T14:52:42.868+0000] {local_task_job.py:212} INFO - Task exited with return code 0
[2023-03-21T14:52:42.932+0000] {taskinstance.py:2585} INFO - 1 downstream tasks scheduled from follow-on schedule check
[2023-03-21T15:17:11.261+0000] {taskinstance.py:1084} INFO - Dependencies all met for dep_context=non-requeueable deps ti=<TaskInstance: batch_pipeline.extract_database_tables scheduled__2023-03-20T00:00:00+00:00 [queued]>
[2023-03-21T15:17:11.280+0000] {taskinstance.py:1084} INFO - Dependencies all met for dep_context=requeueable deps ti=<TaskInstance: batch_pipeline.extract_database_tables scheduled__2023-03-20T00:00:00+00:00 [queued]>
[2023-03-21T15:17:11.282+0000] {taskinstance.py:1282} INFO - 
--------------------------------------------------------------------------------
[2023-03-21T15:17:11.284+0000] {taskinstance.py:1283} INFO - Starting attempt 3 of 3
[2023-03-21T15:17:11.285+0000] {taskinstance.py:1284} INFO - 
--------------------------------------------------------------------------------
[2023-03-21T15:17:11.318+0000] {taskinstance.py:1303} INFO - Executing <Task(PythonOperator): extract_database_tables> on 2023-03-20 00:00:00+00:00
[2023-03-21T15:17:11.330+0000] {standard_task_runner.py:55} INFO - Started process 3163 to run task
[2023-03-21T15:17:11.338+0000] {standard_task_runner.py:82} INFO - Running: ['***', 'tasks', 'run', 'batch_pipeline', 'extract_database_tables', 'scheduled__2023-03-20T00:00:00+00:00', '--job-id', '117', '--raw', '--subdir', 'DAGS_FOLDER/batch_pipeline.py', '--cfg-path', '/tmp/tmp3731b4ps']
[2023-03-21T15:17:11.341+0000] {standard_task_runner.py:83} INFO - Job 117: Subtask extract_database_tables
[2023-03-21T15:17:11.475+0000] {task_command.py:388} INFO - Running <TaskInstance: batch_pipeline.extract_database_tables scheduled__2023-03-20T00:00:00+00:00 [running]> on host 070f7bf9e1a1
[2023-03-21T15:17:11.605+0000] {taskinstance.py:1511} INFO - Exporting the following env vars:
AIRFLOW_CTX_DAG_OWNER=Pedrosa
AIRFLOW_CTX_DAG_ID=batch_pipeline
AIRFLOW_CTX_TASK_ID=extract_database_tables
AIRFLOW_CTX_EXECUTION_DATE=2023-03-20T00:00:00+00:00
AIRFLOW_CTX_TRY_NUMBER=3
AIRFLOW_CTX_DAG_RUN_ID=scheduled__2023-03-20T00:00:00+00:00
[2023-03-21T15:17:11.614+0000] {logging_mixin.py:137} INFO - Erro: name 'create_engine' is not defined
[2023-03-21T15:17:11.616+0000] {python.py:177} INFO - Done. Returned value was: None
[2023-03-21T15:17:11.636+0000] {taskinstance.py:1326} INFO - Marking task as SUCCESS. dag_id=batch_pipeline, task_id=extract_database_tables, execution_date=20230320T000000, start_date=20230321T151711, end_date=20230321T151711
[2023-03-21T15:17:11.676+0000] {local_task_job.py:212} INFO - Task exited with return code 0
[2023-03-21T15:17:11.730+0000] {taskinstance.py:2585} INFO - 1 downstream tasks scheduled from follow-on schedule check
[2023-03-21T15:31:43.972+0000] {taskinstance.py:1084} INFO - Dependencies all met for dep_context=non-requeueable deps ti=<TaskInstance: batch_pipeline.extract_database_tables scheduled__2023-03-20T00:00:00+00:00 [queued]>
[2023-03-21T15:31:44.025+0000] {taskinstance.py:1084} INFO - Dependencies all met for dep_context=requeueable deps ti=<TaskInstance: batch_pipeline.extract_database_tables scheduled__2023-03-20T00:00:00+00:00 [queued]>
[2023-03-21T15:31:44.042+0000] {taskinstance.py:1282} INFO - 
--------------------------------------------------------------------------------
[2023-03-21T15:31:44.045+0000] {taskinstance.py:1283} INFO - Starting attempt 3 of 3
[2023-03-21T15:31:44.051+0000] {taskinstance.py:1284} INFO - 
--------------------------------------------------------------------------------
[2023-03-21T15:31:44.180+0000] {taskinstance.py:1303} INFO - Executing <Task(PythonOperator): extract_database_tables> on 2023-03-20 00:00:00+00:00
[2023-03-21T15:31:44.230+0000] {standard_task_runner.py:55} INFO - Started process 3440 to run task
[2023-03-21T15:31:44.266+0000] {standard_task_runner.py:82} INFO - Running: ['***', 'tasks', 'run', 'batch_pipeline', 'extract_database_tables', 'scheduled__2023-03-20T00:00:00+00:00', '--job-id', '129', '--raw', '--subdir', 'DAGS_FOLDER/batch_pipeline.py', '--cfg-path', '/tmp/tmp0orlt4lk']
[2023-03-21T15:31:44.275+0000] {standard_task_runner.py:83} INFO - Job 129: Subtask extract_database_tables
[2023-03-21T15:31:44.845+0000] {task_command.py:388} INFO - Running <TaskInstance: batch_pipeline.extract_database_tables scheduled__2023-03-20T00:00:00+00:00 [running]> on host 070f7bf9e1a1
[2023-03-21T15:31:45.471+0000] {taskinstance.py:1511} INFO - Exporting the following env vars:
AIRFLOW_CTX_DAG_OWNER=Pedrosa
AIRFLOW_CTX_DAG_ID=batch_pipeline
AIRFLOW_CTX_TASK_ID=extract_database_tables
AIRFLOW_CTX_EXECUTION_DATE=2023-03-20T00:00:00+00:00
AIRFLOW_CTX_TRY_NUMBER=3
AIRFLOW_CTX_DAG_RUN_ID=scheduled__2023-03-20T00:00:00+00:00
[2023-03-21T15:31:45.502+0000] {logging_mixin.py:137} INFO - Erro: (psycopg2.OperationalError) connection to server at "localhost" (127.0.0.1), port 5432 failed: Connection refused
	Is the server running on that host and accepting TCP/IP connections?
connection to server at "localhost" (::1), port 5432 failed: Cannot assign requested address
	Is the server running on that host and accepting TCP/IP connections?

(Background on this error at: https://sqlalche.me/e/14/e3q8)
[2023-03-21T15:31:45.506+0000] {python.py:177} INFO - Done. Returned value was: None
[2023-03-21T15:31:45.557+0000] {taskinstance.py:1326} INFO - Marking task as SUCCESS. dag_id=batch_pipeline, task_id=extract_database_tables, execution_date=20230320T000000, start_date=20230321T153143, end_date=20230321T153145
[2023-03-21T15:31:45.707+0000] {local_task_job.py:212} INFO - Task exited with return code 0
[2023-03-21T15:31:45.943+0000] {taskinstance.py:2585} INFO - 1 downstream tasks scheduled from follow-on schedule check
[2023-03-21T15:52:28.903+0000] {taskinstance.py:1084} INFO - Dependencies all met for dep_context=non-requeueable deps ti=<TaskInstance: batch_pipeline.extract_database_tables scheduled__2023-03-20T00:00:00+00:00 [queued]>
[2023-03-21T15:52:28.923+0000] {taskinstance.py:1084} INFO - Dependencies all met for dep_context=requeueable deps ti=<TaskInstance: batch_pipeline.extract_database_tables scheduled__2023-03-20T00:00:00+00:00 [queued]>
[2023-03-21T15:52:28.926+0000] {taskinstance.py:1282} INFO - 
--------------------------------------------------------------------------------
[2023-03-21T15:52:28.928+0000] {taskinstance.py:1283} INFO - Starting attempt 3 of 3
[2023-03-21T15:52:28.929+0000] {taskinstance.py:1284} INFO - 
--------------------------------------------------------------------------------
[2023-03-21T15:52:28.964+0000] {taskinstance.py:1303} INFO - Executing <Task(PythonOperator): extract_database_tables> on 2023-03-20 00:00:00+00:00
[2023-03-21T15:52:28.974+0000] {standard_task_runner.py:55} INFO - Started process 3821 to run task
[2023-03-21T15:52:28.983+0000] {standard_task_runner.py:82} INFO - Running: ['***', 'tasks', 'run', 'batch_pipeline', 'extract_database_tables', 'scheduled__2023-03-20T00:00:00+00:00', '--job-id', '153', '--raw', '--subdir', 'DAGS_FOLDER/load_csv.py', '--cfg-path', '/tmp/tmpz3p0yxzb']
[2023-03-21T15:52:28.986+0000] {standard_task_runner.py:83} INFO - Job 153: Subtask extract_database_tables
[2023-03-21T15:52:29.133+0000] {task_command.py:388} INFO - Running <TaskInstance: batch_pipeline.extract_database_tables scheduled__2023-03-20T00:00:00+00:00 [running]> on host 070f7bf9e1a1
[2023-03-21T15:52:29.273+0000] {taskinstance.py:1511} INFO - Exporting the following env vars:
AIRFLOW_CTX_DAG_OWNER=Pedrosa
AIRFLOW_CTX_DAG_ID=batch_pipeline
AIRFLOW_CTX_TASK_ID=extract_database_tables
AIRFLOW_CTX_EXECUTION_DATE=2023-03-20T00:00:00+00:00
AIRFLOW_CTX_TRY_NUMBER=3
AIRFLOW_CTX_DAG_RUN_ID=scheduled__2023-03-20T00:00:00+00:00
[2023-03-21T15:52:29.321+0000] {logging_mixin.py:137} INFO - Erro: (psycopg2.OperationalError) connection to server at "host.docker.internal" (192.168.65.2), port 5432 failed: FATAL:  password authentication failed for user "postgres"

(Background on this error at: https://sqlalche.me/e/14/e3q8)
[2023-03-21T15:52:29.326+0000] {python.py:177} INFO - Done. Returned value was: None
[2023-03-21T15:52:29.361+0000] {taskinstance.py:1326} INFO - Marking task as SUCCESS. dag_id=batch_pipeline, task_id=extract_database_tables, execution_date=20230320T000000, start_date=20230321T155228, end_date=20230321T155229
[2023-03-21T15:52:29.445+0000] {local_task_job.py:212} INFO - Task exited with return code 0
[2023-03-21T15:52:29.568+0000] {taskinstance.py:2585} INFO - 1 downstream tasks scheduled from follow-on schedule check
